Workbook

Sheet Instructions
A1: MS Excel Practical Exam
A2: Total Questions: 30
A3: Difficulty Level: Medium
A4: Syllabus: Formulas, Logical Functions, Lookups, INDEX-MATCH, Pivot Tables & Charts, Data Analysis
A5: Attempt all questions using appropriate Excel tools/functions.

Sheet Sales_Data
A1: Order_ID | B1: Region | C1: Salesperson | D1: Product | E1: Quantity | F1: Unit_Price | G1: Sales_Date
A2: 301 | B2: North | C2: Amit | D2: Laptop | E2: 2 | F2: 45000 | G2: 05-01-2025
A3: 302 | B3: South | C3: Riya | D3: Mobile | E3: 5 | F3: 15000 | G3: 07-01-2025
A4: 303 | B4: East | C4: Kunal | D4: Tablet | E4: 3 | F4: 18000 | G4: 10-01-2025
A5: 304 | B5: West | C5: Neha | D5: Laptop | E5: 1 | F5: 45000 | G5: 12-01-2025
A6: 305 | B6: North | C6: Amit | D6: Mobile | E6: 4 | F6: 15000 | G6: 15-01-2025
A7: 306 | B7: South | C7: Riya | D7: Laptop | E7: 2 | F7: 45000 | G7: 18-01-2025

Sheet Product_Master
A1: Product | B1: Category | C1: GST_%
A2: Laptop | B2: Electronics | C2: 18
A3: Mobile | B3: Electronics | C3: 12
A4: Tablet | B4: Electronics | C4: 12

Sheet Student_Marks
A1: Student_ID | B1: Name | C1: Maths | D1: Statistics | E1: Excel | F1: Attendance_%
A2: 1 | B2: Rahul | C2: 78 | D2: 82 | E2: 85 | F2: 92
A3: 2 | B3: Sneha | C3: 88 | D3: 91 | E3: 90 | F3: 96
A4: 3 | B4: Arjun | C4: 65 | D4: 70 | E4: 72 | F4: 85
A5: 4 | B5: Pooja | C5: 92 | D5: 89 | E5: 94 | F5: 98
A6: 5 | B6: Vikas | C6: 55 | D6: 60 | E6: 58 | F6: 80

Sheet Questions
A1: 1. Calculate Total Sales for each order (Quantity × Unit_Price). | J1: 2
A2: 2. Calculate GST Amount using VLOOKUP from Product_Master. | J2: 2
A3: 3. Find Final Amount payable (Total Sales + GST). | J3: 2
A4: 4. Find Grand Total of Final Amount. | J4: 2
A5: 5. Count total number of orders using COUNTA. | J5: 2
A6: 6. Find Region-wise total sales using SUMIF. | J6: 2
A7: 7. Use IF to classify Quantity as High (>3) or Low (<=3). | J7: 2
A8: 8. Find the maximum and minimum Final Amount. | J8: 2
A9: 9. Extract month name from Sales_Date. | J9: 2
A10: 10. Sort Sales_Data by Final Amount (Descending). | J10: 2
A11: 11. Use INDEX-MATCH to fetch Product Category. | J11: 2
A12: 12. Calculate average marks of each student. | J12: 2
... A30: 30. Protect the Student_Marks sheet. | J30: 2
J32: =SUM(J1:J30) -> 60

Sheet Answers
A1: 1. Calculate Total Sales for each order (Quantity × Unit_Price).
B3: Order_ID | C3: Region | D3: Salesperson | E3: Product | F3: Quantity | G3: Unit_Price | H3: Sales_Date | I3: Total Sales
B4: 301 | C4: North | D4: Amit | E4: Laptop | F4: 2 | G4: 45000 | H4: 05-01-2025 | I4: =F4*G4 -> 90000
B5: 302 | C5: South | D5: Riya | E5: Mobile | F5: 5 | G5: 15000 | H5: 07-01-2025 | I5: =F5*G5 -> 75000
B6: 303 | C6: East | D6: Kunal | E6: Tablet | F6: 3 | G6: 18000 | H6: 10-01-2025 | I6: =F6*G6 -> 54000
B7: 304 | C7: West | D7: Neha | E7: Laptop | F7: 1 | G7: 45000 | H7: 12-01-2025 | I7: =F7*G7 -> 45000
B8: 305 | C8: North | D8: Amit | E8: Mobile | F8: 4 | G8: 15000 | H8: 15-01-2025 | I8: =F8*G8 -> 60000
B9: 306 | C9: South | D9: Riya | E9: Laptop | F9: 2 | G9: 45000 | H9: 18-01-2025 | I9: =F9*G9 -> 90000
A11: 2. Calculate GST Amount using VLOOKUP from Product_Master.
B13: Order_ID | C13: Region | D13: Salesperson | E13: Product | F13: Quantity | G13: Unit_Price | H13: Sales_Date | I13: Total Sales | J13: GST% | K13: GST Amount
B14: 301 | C14: North | D14: Amit | E14: Laptop | F14: 2 | G14: 45000 | H14: 05-01-2025 | I14: =F14*G14 -> 90000 | J14: =VLOOKUP(E14,Product_Master!A:C,3,0) -> 18 | K14: =I14*J14/100 -> 16200
B15: 302 | C15: South | D15: Riya | E15: Mobile | F15: 5 | G15: 15000 | H15: 07-01-2025 | I15: =F15*G15 -> 75000 | J15: =VLOOKUP(E15,Product_Master!A:C,3,0) -> 12 | K15: =I15*J15/100 -> 9000
B16: 303 | C16: East | D16: Kunal | E16: Tablet | F16: 3 | G16: 18000 | H16: 10-01-2025 | I16: =F16*G16 -> 54000 | J16: =VLOOKUP(E16,Product_Master!A:C,3,0) -> 12 | K16: =I16*J16/100 -> 6480
B17: 304 | C17: West | D17: Neha | E17: Laptop | F17: 1 | G17: 45000 | H17: 12-01-2025 | I17: =F17*G17 -> 45000 | J17: =VLOOKUP(E17,Product_Master!A:C,3,0) -> 18 | K17: =I17*J17/100 -> 8100
B18: 305 | C18: North | D18: Amit | E18: Mobile | F18: 4 | G18: 15000 | H18: 15-01-2025 | I18: =F18*G18 -> 60000 | J18: =VLOOKUP(E18,Product_Master!A:C,3,0) -> 12 | K18: =I18*J18/100 -> 7200
B19: 306 | C19: South | D19: Riya | E19: Laptop | F19: 2 | G19: 45000 | H19: 18-01-2025 | I19: =F19*G19 -> 90000 | J19: =VLOOKUP(E19,Product_Master!A:C,3,0) -> 18 | K19: =I19*J19/100 -> 16200
A21: 3. Find Final Amount payable (Total Sales + GST).
B23: Order_ID | C23: Region | D23: Salesperson | E23: Product | F23: Quantity | G23: Unit_Price | H23: Sales_Date | I23: Total Sales | J23: GST% | K23: GST Amount | L23: Final Payable Amount
B24: 301 | C24: North | D24: Amit | E24: Laptop | F24: 2 | G24: 45000 | H24: 05-01-2025 | I24: =F24*G24 -> 90000 | J24: =VLOOKUP(E24,Product_Master!A:C,3,0) -> 18 | K24: =I24*J24/100 -> 16200 | L24: =I24+K24 -> 106200
B25: 302 | C25: South | D25: Riya | E25: Mobile | F25: 5 | G25: 15000 | H25: 07-01-2025 | I25: =F25*G25 -> 75000 | J25: =VLOOKUP(E25,Product_Master!A:C,3,0) -> 12 | K25: =I25*J25/100 -> 9000 | L25: =I25+K25 -> 84000
B26: 303 | C26: East | D26: Kunal | E26: Tablet | F26: 3 | G26: 18000 | H26: 10-01-2025 | I26: =F26*G26 -> 54000 | J26: =VLOOKUP(E26,Product_Master!A:C,3,0) -> 12 | K26: =I26*J26/100 -> 6480 | L26: =I26+K26 -> 60480
B27: 304 | C27: West | D27: Neha | E27: Laptop | F27: 1 | G27: 45000 | H27: 12-01-2025 | I27: =F27*G27 -> 45000 | J27: =VLOOKUP(E27,Product_Master!A:C,3,0) -> 18 | K27: =I27*J27/100 -> 8100 | L27: =I27+K27 -> 53100
B28: 305 | C28: North | D28: Amit | E28: Mobile | F28: 4 | G28: 15000 | H28: 15-01-2025 | I28: =F28*G28 -> 60000 | J28: =VLOOKUP(E28,Product_Master!A:C,3,0) -> 12 | K28: =I28*J28/100 -> 7200 | L28: =I28+K28 -> 67200
B29: 306 | C29: South | D29: Riya | E29: Laptop | F29: 2 | G29: 45000 | H29: 18-01-2025 | I29: =F29*G29 -> 90000 | J29: =VLOOKUP(E29,Product_Master!A:C,3,0) -> 18 | K29: =I29*J29/100 -> 16200 | L29: =I29+K29 -> 106200
A31: 4. Find Grand Total of Final Amount
B33: Order_ID | C33: Region | D33: Salesperson | E33: Product | F33: Quantity | G33: Unit_Price | H33: Sales_Date | I33: Total Sales | J33: GST% | K33: GST Amount | L33: Final Payable Amount
B34: 301 | C34: North | D34: Amit | E34: Laptop | F34: 2 | G34: 45000 | H34: 05-01-2025 | I34: =F34*G34 -> 90000 | J34: =VLOOKUP(E34,Product_Master!A:C,3,0) -> 18 | K34: =I34*J34/100 -> 16200 | L34: =I34+K34 -> 106200
B35: 302 | C35: South | D35: Riya | E35: Mobile | F35: 5 | G35: 15000 | H35: 07-01-2025 | I35: =F35*G35 -> 75000 | J35: =VLOOKUP(E35,Product_Master!A:C,3,0) -> 12 | K35: =I35*J35/100 -> 9000 | L35: =I35+K35 -> 84000
B36: 303 | C36: East | D36: Kunal | E36: Tablet | F36: 3 | G36: 18000 | H36: 10-01-2025 | I36: =F36*G36 -> 54000 | J36: =VLOOKUP(E36,Product_Master!A:C,3,0) -> 12 | K36: =I36*J36/100 -> 6480 | L36: =I36+K36 -> 60480
B37: 304 | C37: West | D37: Neha | E37: Laptop | F37: 1 | G37: 45000 | H37: 12-01-2025 | I37: =F37*G37 -> 45000 | J37: =VLOOKUP(E37,Product_Master!A:C,3,0) -> 18 | K37: =I37*J37/100 -> 8100 | L37: =I37+K37 -> 53100
B38: 305 | C38: North | D38: Amit | E38: Mobile | F38: 4 | G38: 15000 | H38: 15-01-2025 | I38: =F38*G38 -> 60000 | J38: =VLOOKUP(E38,Product_Master!A:C,3,0) -> 12 | K38: =I38*J38/100 -> 7200 | L38: =I38+K38 -> 67200
B39: 306 | C39: South | D39: Riya | E39: Laptop | F39: 2 | G39: 45000 | H39: 18-01-2025 | I39: =F39*G39 -> 90000 | J39: =VLOOKUP(E39,Product_Master!A:C,3,0) -> 18 | K39: =I39*J39/100 -> 16200 | L39: =I39+K39 -> 106200
L40: =SUM(L34:L39) -> 477180
A42: 5. Count total number of orders using COUNTA
A44: Total number of orders | B44: =COUNTA(Sales_Data!A2:A8) -> 6
A46: 6. Find Region-wise total sales using SUMIF
B48: Order_ID | C48: Region | D48: Salesperson | E48: Product | F48: Quantity | G48: Unit_Price | H48: Sales_Date | I48: Total Sales | L48: Region | M48: Total Sales
B49: 301 | C49: North | D49: Amit | E49: Laptop | F49: 2 | G49: 45000 | H49: 05-01-2025 | I49: =F49*G49 -> 90000 | L49: North | M49: =SUMIF(C49:C54,L49,I49:I54) -> 150000
B50: 302 | C50: South | D50: Riya | E50: Mobile | F50: 5 | G50: 15000 | H50: 07-01-2025 | I50: =F50*G50 -> 75000 | L50: South | M50: =SUMIF(C50:C55,L50,I50:I55) -> 165000
B51: 303 | C51: East | D51: Kunal | E51: Tablet | F51: 3 | G51: 18000 | H51: 10-01-2025 | I51: =F51*G51 -> 54000 | L51: East | M51: =SUMIF(C51:C56,L51,I51:I56) -> 54000
...
